Workbook

Sheet Assumptions
A1: OneCoco financial model - assumptions (blue = editable input). All USD unless stated. Modeled estimates, NOT verified facts.
A3: FX rate JMD per USD | B3: 158 | C3: Aggregator rate 26 Sep 2026 (exchange-rates.org). Re-check BOJ rate at use.
A4: Coconuts per order | B4: 1.2 | C4: Assumed mix: 70% Classic(1), 15% Coco-for-Two(2), 15% other
A5: Supplies per order $ (straw, napkin, ice, cup) | B5: 0.25 | C5: ASSUMPTION - validate
A6: Card/online payment share of orders | B6: 0.6 | C6: ASSUMPTION - validate in pilot
A7: Card fee % of charge | B7: 0.06 | C7: ASSUMPTION ~PayPal cross-border commercial rate; verify actual contract
A8: Card fixed fee $ per txn | B8: 0.49 | C8: ASSUMPTION; verify
A9: Cash shrinkage % of cash revenue | B9: 0.015 | C9: ASSUMPTION
A10: Orders one runner can serve per 8h shift | B10: 20 | C10: ASSUMPTION ~2.5/h; validate
A11: Runner per-delivery pay $ (on top of guaranteed shift pay) | B11: 1 | C11: ASSUMPTION ~J$160; legal classification must be confirmed
A12: Ops coordinator $/month (per 3 beaches, from M2) | B12: 650 | C12: ASSUMPTION ~J$100k/mo loaded
A13: Tech/SaaS $/month | B13: 130 | C13: Vercel, Supabase, Resend, monitoring, domain - verify plan prices
A14: Bookkeeping/accounting $/month | B14: 120 | C14: ASSUMPTION
... A17: Beach setup capex $ per new beach | B17: 1700 | C17: Cart/cooler 600, tools 200, uniforms/signage 150, phone 180, stock 200, cash float 150, training 100, QR collateral 120
A18: Contingency on pre-launch one-time | B18: 0.15
A19: Days per month | B19: 30
A22: Pre-launch one-time costs (USD) | B22: USD | C22: Status / source
A23: Incorporation + name reservation (COJ ~J$28k) | B23: 180 | C23: Mandatory-ish; fees from 3rd-party/handouts, verify at orcjamaica.com
A24: Accountant setup: TRN, payroll registrations, books | B24: 300 | C24: Mandatory; quote needed
A25: Jamaican attorney: T&Cs, privacy, refund policy, staff & partner contracts, beach-access review | B25: 1500 | C25: Mandatory; quote needed
A26: OIC data-controller registration | B26: 100 | C26: Mandatory; fee unverified
A27: Trademark + domain (after name decision) | B27: 400 | C27: Recommended; JIPO fees unverified
A28: Insurance deposit / first premium | B28: 700 | C28: Mandatory; quote needed
A29: Food handler permits + medicals (5 people) | B29: 60 | C29: Mandatory; fee from 2011 source
A30: Beach access / vending permissions & fees | B30: 500 | C30: UNKNOWN - placeholder; could be higher
A31: Tech hardening: Next.js upgrade, live payments, E2E tests, monitoring, backups | B31: 3500 | C31: Contractor est. ~100h; see tech audit
A32: Content: photography/video, signage design | B32: 800 | C32: Optional but strongly advised
A33: Pre-launch marketing (landing, partner outreach) | B33: 500 | C33: Optional
A34: Total pre-launch one-time (before contingency) | B34: =SUM(B23:B33) -> 8540
A35: Total with contingency | B35: =B34*(1+Assumptions!$B$18) -> 9821
A37: Seasonality factor by launch month (ASSUMPTION - no verified Jamaica beach-demand series)
A38: Dec-26 | B38: 1
A39: Jan-27 | B39: 1.1
A40: Feb-27 | B40: 1.1
A41: Mar-27 | B41: 1.1
A42: Apr-27 | B42: 0.9
A43: May-27 | B43: 0.7
A44: Jun-27 | B44: 0.6
A45: Jul-27 | B45: 0.7
A46: Aug-27 | B46: 0.7
...

Sheet Conservative
A1: Conservative scenario - monthly model (USD). Launch month M1 = Dec 2026
A2: Mature orders/day per beach | B2: 9
A3: Ramp months to maturity | B3: 5
A4: Avg product revenue per order $ (pre-promo) | B4: 7.6
A5: Promo discount % of product rev | B5: 0.08
A6: Coconut cost per nut $ | B6: 1.2
A7: Support/refund loss % revenue | B7: 0.05
A8: Runner guaranteed shift pay per position-day $ (loaded) | B8: 40
A9: Marketing $/month | B9: 500
A10: Delivery fee $ per order | B10: 2
A12: Line | B12: M0 | C12: M1 | D12: M2 | E12: M3 | F12: M4 | G12: M5 | H12: M6 | I12: M7 | J12: M8 | K12: M9 | L12: M10 | M12: M11 | N12: M12 | O12: 12-mo total
A13: Month index | B13: 0 | C13: 1 | D13: 2 | E13: 3 | F13: 4 | G13: 5 | H13: 6 | I13: 7 | J13: 8 | K13: 9 | L13: 10 | M13: 11 | N13: 12
A14: Calendar month | C14: Dec-26 | D14: Jan-27 | E14: Feb-27 | F14: Mar-27 | G14: Apr-27 | H14: May-27 | I14: Jun-27 | J14: Jul-27 | K14: Aug-27 | L14: Sep-27 | M14: Oct-27 | N14: Nov-27
A15: Season factor | C15: =Assumptions!$B$38 -> 1 | D15: =Assumptions!$B$39 -> 1.1 | E15: =Assumptions!$B$40 -> 1.1 | F15: =Assumptions!$B$41 -> 1.1 | G15: =Assumptions!$B$42 -> 0.9 | H15: =Assumptions!$B$43 -> 0.7 | I15: =Assumptions!$B$44 -> 0.6 | J15: =Assumptions!$B$45 -> 0.7 | K15: =Assumptions!$B$46 -> 0.7 | L15: =Assumptions!$B$47 -> 0.5 | M15: =Assumptions!$B$48 -> 0.5 | N15: =Assumptions!$B$49 -> 0.7
A16: New beaches opened (input plan) | C16: 1 | D16: 0 | E16: 0 | F16: 0 | G16: 0 | H16: 0 | I16: 0 | J16: 1 | K16: 0 | L16: 0 | M16: 0 | N16: 0
A17: Active beaches | B17: 0 | C17: =B17+C16 -> 1 | D17: =C17+D16 -> 1 | E17: =D17+E16 -> 1 | F17: =E17+F16 -> 1 | G17: =F17+G16 -> 1 | H17: =G17+H16 -> 1 | I17: =H17+I16 -> 1 | J17: =I17+J16 -> 2 | ... N17: =M17+N16 -> 2
A18: Beach-equivalents (ramped) | C18: =SUMPRODUCT($C$16:C16,(C$13-$C$13:C$13+1+$B$3-ABS(C$13-$C$13:C$13+1-$B$3))/(2*$B$3)) -> 0.2 | D18: =SUMPRODUCT($C$16:D16,(D$13-$C$13:D$13+1+$B$3-ABS(D$13-$C$13:D$13+1-$B$3))/(2*$B$3)) -> 0.4 | E18: =SUMPRODUCT($C$16:E16,(E$13-$C$13:E$13+1+$B$3-ABS(E$13-$C$13:E$13+1-$B$3))/(2*$B$3)) -> 0.6 | F18: =SUMPRODUCT($C$16:F16,(F$13-$C$13:F$13+1+$B$3-ABS(F$13-$C$13:F$13+1-$B$3))/(2*$B$3)) -> 0.8 | G18: =SUMPRODUCT($C$16:G16,(G$13-$C$13:G$13+1+$B$3-ABS(G$13-$C$13:G$13+1-$B$3))/(2*$B$3)) -> 1 | H18: =SUMPRODUCT($C$16:H16,(H$13-$C$13:H$13+1+$B$3-ABS(H$13-$C$13:H$13+1-$B$3))/(2*$B$3)) -> 1 | I18: =SUMPRODUCT($C$16:I16,(I$13-$C$13:I$13+1+$B$3-ABS(I$13-$C$13:I$13+1-$B$3))/(2*$B$3)) -> 1 | J18: =SUMPRODUCT($C$16:J16,(J$13-$C$13:J$13+1+$B$3-ABS(J$13-$C$13:J$13+1-$B$3))/(2*$B$3)) -> 1.2 | ... N18: =SUMPRODUCT($C$16:N16,(N$13-$C$13:N$13+1+$B$3-ABS(N$13-$C$13:N$13+1-$B$3))/(2*$B$3)) -> 2
A19: Orders/day (all beaches) | C19: =C18*$B$2*C15 -> 1.8 | D19: =D18*$B$2*D15 -> 3.96 | E19: =E18*$B$2*E15 -> 5.94 | F19: =F18*$B$2*F15 -> 7.92 | G19: =G18*$B$2*G15 -> 8.1 | H19: =H18*$B$2*H15 -> 6.3 | I19: =I18*$B$2*I15 -> 5.4 | J19: =J18*$B$2*J15 -> 7.56 | ... N19: =N18*$B$2*N15 -> 12.6
A20: Orders/month | C20: =C19*Assumptions!$B$19 -> 54 | D20: =D19*Assumptions!$B$19 -> 118.8 | E20: =E19*Assumptions!$B$19 -> 178.2 | F20: =F19*Assumptions!$B$19 -> 237.6 | G20: =G19*Assumptions!$B$19 -> 243 | H20: =H19*Assumptions!$B$19 -> 189 | I20: =I19*Assumptions!$B$19 -> 162 | J20: =J19*Assumptions!$B$19 -> 226.8 | ... N20: =N19*Assumptions!$B$19 -> 378 | O20: =SUM(B20:N20) -> 2511
A21: Product revenue (net of promo) | C21: =C20*$B$4*(1-$B$5) -> 377.568 | D21: =D20*$B$4*(1-$B$5) -> 830.6496 | E21: =E20*$B$4*(1-$B$5) -> 1245.9744 | F21: =F20*$B$4*(1-$B$5) -> 1661.2992 | G21: =G20*$B$4*(1-$B$5) -> 1699.056 | H21: =H20*$B$4*(1-$B$5) -> 1321.488 | I21: =I20*$B$4*(1-$B$5) -> 1132.704 | J21: =J20*$B$4*(1-$B$5) -> 1585.7856 | ... N21: =N20*$B$4*(1-$B$5) -> 2642.976 | O21: =SUM(B21:N21) -> 17556.912
A22: Delivery fee revenue | C22: =C20*$B$10 -> 108 | D22: =D20*$B$10 -> 237.6 | E22: =E20*$B$10 -> 356.4 | F22: =F20*$B$10 -> 475.2 | G22: =G20*$B$10 -> 486 | H22: =H20*$B$10 -> 378 | I22: =I20*$B$10 -> 324 | J22: =J20*$B$10 -> 453.6 | ... N22: =N20*$B$10 -> 756 | O22: =SUM(B22:N22) -> 5022
A23: TOTAL REVENUE | C23: =C21+C22 -> 485.568 | D23: =D21+D22 -> 1068.2496 | E23: =E21+E22 -> 1602.3744 | F23: =F21+F22 -> 2136.4992 | G23: =G21+G22 -> 2185.056 | H23: =H21+H22 -> 1699.488 | I23: =I21+I22 -> 1456.704 | J23: =J21+J22 -> 2039.3856 | ... N23: =N21+N22 -> 3398.976 | O23: =SUM(B23:N23) -> 22578.912
A24: Coconut cost | C24: =C20*Assumptions!$B$4*$B$6 -> 77.76 | D24: =D20*Assumptions!$B$4*$B$6 -> 171.072 | E24: =E20*Assumptions!$B$4*$B$6 -> 256.608 | F24: =F20*Assumptions!$B$4*$B$6 -> 342.144 | G24: =G20*Assumptions!$B$4*$B$6 -> 349.92 | H24: =H20*Assumptions!$B$4*$B$6 -> 272.16 | I24: =I20*Assumptions!$B$4*$B$6 -> 233.28 | J24: =J20*Assumptions!$B$4*$B$6 -> 326.592 | ... N24: =N20*Assumptions!$B$4*$B$6 -> 544.32 | O24: =SUM(B24:N24) -> 3615.84
A25: Supplies | C25: =C20*Assumptions!$B$5 -> 13.5 | D25: =D20*Assumptions!$B$5 -> 29.7 | E25: =E20*Assumptions!$B$5 -> 44.55 | F25: =F20*Assumptions!$B$5 -> 59.4 | G25: =G20*Assumptions!$B$5 -> 60.75 | H25: =H20*Assumptions!$B$5 -> 47.25 | I25: =I20*Assumptions!$B$5 -> 40.5 | J25: =J20*Assumptions!$B$5 -> 56.7 | ... N25: =N20*Assumptions!$B$5 -> 94.5 | O25: =SUM(B25:N25) -> 627.75
A26: Payment fees | C26: =Assumptions!$B$6*(Assumptions!$B$7*C23+Assumptions!$B$8*C20) -> 33.356448 | D26: =Assumptions!$B$6*(Assumptions!$B$7*D23+Assumptions!$B$8*D20) -> 73.384186 | E26: =Assumptions!$B$6*(Assumptions!$B$7*E23+Assumptions!$B$8*E20) -> 110.07628 | F26: =Assumptions!$B$6*(Assumptions!$B$7*F23+Assumptions!$B$8*F20) -> 146.76837 | G26: =Assumptions!$B$6*(Assumptions!$B$7*G23+Assumptions!$B$8*G20) -> 150.10402 | H26: =Assumptions!$B$6*(Assumptions!$B$7*H23+Assumptions!$B$8*H20) -> 116.74757 | I26: =Assumptions!$B$6*(Assumptions!$B$7*I23+Assumptions!$B$8*I20) -> 100.06934 | J26: =Assumptions!$B$6*(Assumptions!$B$7*J23+Assumptions!$B$8*J20) -> 140.09708 | ... N26: =Assumptions!$B$6*(Assumptions!$B$7*N23+Assumptions!$B$8*N20) -> 233.49514 | O26: =SUM(B26:N26) -> 1551.0748
A27: Cash shrinkage | C27: =(1-Assumptions!$B$6)*Assumptions!$B$9*C23 -> 2.913408 | D27: =(1-Assumptions!$B$6)*Assumptions!$B$9*D23 -> 6.4094976 | E27: =(1-Assumptions!$B$6)*Assumptions!$B$9*E23 -> 9.6142464 | F27: =(1-Assumptions!$B$6)*Assumptions!$B$9*F23 -> 12.818995 | G27: =(1-Assumptions!$B$6)*Assumptions!$B$9*G23 -> 13.110336 | H27: =(1-Assumptions!$B$6)*Assumptions!$B$9*H23 -> 10.196928 | I27: =(1-Assumptions!$B$6)*Assumptions!$B$9*I23 -> 8.740224 | J27: =(1-Assumptions!$B$6)*Assumptions!$B$9*J23 -> 12.236314 | ... N27: =(1-Assumptions!$B$6)*Assumptions!$B$9*N23 -> 20.393856 | O27: =SUM(B27:N27) -> 135.47347
A28: Support/refund losses | C28: =$B$7*C23 -> 24.2784 | D28: =$B$7*D23 -> 53.41248 | E28: =$B$7*E23 -> 80.11872 | F28: =$B$7*F23 -> 106.82496 | G28: =$B$7*G23 -> 109.2528 | H28: =$B$7*H23 -> 84.9744 | I28: =$B$7*I23 -> 72.8352 | J28: =$B$7*J23 -> 101.96928 | ... N28: =$B$7*N23 -> 169.9488 | O28: =SUM(B28:N28) -> 1128.9456
A29: Total variable cost (excl. labour) | C29: =SUM(C24:C28) -> 151.80826 | D29: =SUM(D24:D28) -> 333.97816 | E29: =SUM(E24:E28) -> 500.96724 | F29: =SUM(F24:F28) -> 667.95633 | G29: =SUM(G24:G28) -> 683.13715 | H29: =SUM(H24:H28) -> 531.3289 | I29: =SUM(I24:I28) -> 455.42477 | J29: =SUM(J24:J28) -> 637.59468 | ... N29: =SUM(N24:N28) -> 1062.6578 | O29: =SUM(B29:N29) -> 7059.0839
A30: Contribution before labour | C30: =C23-C29 -> 333.75974 | D30: =D23-D29 -> 734.27144 | E30: =E23-E29 -> 1101.4072 | F30: =F23-F29 -> 1468.5429 | G30: =G23-G29 -> 1501.9188 | H30: =H23-H29 -> 1168.1591 | I30: =I23-I29 -> 1001.2792 | J30: =J23-J29 -> 1401.7909 | ... N30: =N23-N29 -> 2336.3182 | O30: =SUM(B30:N30) -> 15519.828
A31: Runner positions per beach | C31: =IF(C17=0,0,MAX(1,ROUNDUP(C19/C17/Assumptions!$B$10,0))) -> 1 | D31: =IF(D17=0,0,MAX(1,ROUNDUP(D19/D17/Assumptions!$B$10,0))) -> 1 | E31: =IF(E17=0,0,MAX(1,ROUNDUP(E19/E17/Assumptions!$B$10,0))) -> 1 | F31: =IF(F17=0,0,MAX(1,ROUNDUP(F19/F17/Assumptions!$B$10,0))) -> 1 | G31: =IF(G17=0,0,MAX(1,ROUNDUP(G19/G17/Assumptions!$B$10,0))) -> 1 | H31: =IF(H17=0,0,MAX(1,ROUNDUP(H19/H17/Assumptions!$B$10,0))) -> 1 | I31: =IF(I17=0,0,MAX(1,ROUNDUP(I19/I17/Assumptions!$B$10,0))) -> 1 | J31: =IF(J17=0,0,MAX(1,ROUNDUP(J19/J17/Assumptions!$B$10,0))) -> 1 | ... N31: =IF(N17=0,0,MAX(1,ROUNDUP(N19/N17/Assumptions!$B$10,0))) -> 1
A32: Runner labour (guaranteed + per-delivery) | C32: =C17*C31*$B$8*Assumptions!$B$19+C20*Assumptions!$B$11 -> 1254 | D32: =D17*D31*$B$8*Assumptions!$B$19+D20*Assumptions!$B$11 -> 1318.8 | E32: =E17*E31*$B$8*Assumptions!$B$19+E20*Assumptions!$B$11 -> 1378.2 | F32: =F17*F31*$B$8*Assumptions!$B$19+F20*Assumptions!$B$11 -> 1437.6 | G32: =G17*G31*$B$8*Assumptions!$B$19+G20*Assumptions!$B$11 -> 1443 | H32: =H17*H31*$B$8*Assumptions!$B$19+H20*Assumptions!$B$11 -> 1389 | I32: =I17*I31*$B$8*Assumptions!$B$19+I20*Assumptions!$B$11 -> 1362 | J32: =J17*J31*$B$8*Assumptions!$B$19+J20*Assumptions!$B$11 -> 2626.8 | ... N32: =N17*N31*$B$8*Assumptions!$B$19+N20*Assumptions!$B$11 -> 2778 | O32: =SUM(B32:N32) -> 22911
A33: Contribution after labour | C33: =C30-C32 -> -920.24026 | D33: =D30-D32 -> -584.52856 | E33: =E30-E32 -> -276.79284 | F33: =F30-F32 -> 30.942874 | G33: =G30-G32 -> 58.918848 | H33: =H30-H32 -> -220.8409 | I33: =I30-I32 -> -360.72077 | J33: =J30-J32 -> -1225.0091 | ... N33: =N30-N32 -> -441.68179 | O33: =SUM(B33:N33) -> -7391.1719
A34: Tech/SaaS | C34: =Assumptions!$B$13 -> 130 | D34: =Assumptions!$B$13 -> 130 | E34: =Assumptions!$B$13 -> 130 | F34: =Assumptions!$B$13 -> 130 | G34: =Assumptions!$B$13 -> 130 | H34: =Assumptions!$B$13 -> 130 | I34: =Assumptions!$B$13 -> 130 | J34: =Assumptions!$B$13 -> 130 | ... N34: =Assumptions!$B$13 -> 130 | O34: =SUM(B34:N34) -> 1560
A35: Accounting + insurance | C35: =Assumptions!$B$14+Assumptions!$B$15 -> 180 | D35: =Assumptions!$B$14+Assumptions!$B$15 -> 180 | E35: =Assumptions!$B$14+Assumptions!$B$15 -> 180 | F35: =Assumptions!$B$14+Assumptions!$B$15 -> 180 | G35: =Assumptions!$B$14+Assumptions!$B$15 -> 180 | H35: =Assumptions!$B$14+Assumptions!$B$15 -> 180 | I35: =Assumptions!$B$14+Assumptions!$B$15 -> 180 | J35: =Assumptions!$B$14+Assumptions!$B$15 -> 180 | ... N35: =Assumptions!$B$14+Assumptions!$B$15 -> 180 | O35: =SUM(B35:N35) -> 2160
A36: Phones/data | C36: =C17*Assumptions!$B$16 -> 25 | D36: =D17*Assumptions!$B$16 -> 25 | E36: =E17*Assumptions!$B$16 -> 25 | F36: =F17*Assumptions!$B$16 -> 25 | G36: =G17*Assumptions!$B$16 -> 25 | H36: =H17*Assumptions!$B$16 -> 25 | I36: =I17*Assumptions!$B$16 -> 25 | J36: =J17*Assumptions!$B$16 -> 50 | ... N36: =N17*Assumptions!$B$16 -> 50 | O36: =SUM(B36:N36) -> 425
A37: Ops coordinators | C37: =IF(C13>=2,ROUNDUP(C17/3,0)*Assumptions!$B$12,0) -> 0 | D37: =IF(D13>=2,ROUNDUP(D17/3,0)*Assumptions!$B$12,0) -> 650 | E37: =IF(E13>=2,ROUNDUP(E17/3,0)*Assumptions!$B$12,0) -> 650 | F37: =IF(F13>=2,ROUNDUP(F17/3,0)*Assumptions!$B$12,0) -> 650 | G37: =IF(G13>=2,ROUNDUP(G17/3,0)*Assumptions!$B$12,0) -> 650 | H37: =IF(H13>=2,ROUNDUP(H17/3,0)*Assumptions!$B$12,0) -> 650 | I37: =IF(I13>=2,ROUNDUP(I17/3,0)*Assumptions!$B$12,0) -> 650 | J37: =IF(J13>=2,ROUNDUP(J17/3,0)*Assumptions!$B$12,0) -> 650 | ... N37: =IF(N13>=2,ROUNDUP(N17/3,0)*Assumptions!$B$12,0) -> 650 | O37: =SUM(B37:N37) -> 7150
A38: Marketing | C38: =$B$9 -> 500 | D38: =$B$9 -> 500 | E38: =$B$9 -> 500 | F38: =$B$9 -> 500 | G38: =$B$9 -> 500 | H38: =$B$9 -> 500 | I38: =$B$9 -> 500 | J38: =$B$9 -> 500 | ... N38: =$B$9 -> 500 | O38: =SUM(B38:N38) -> 6000
A39: Total fixed + marketing | C39: =SUM(C34:C38) -> 835 | D39: =SUM(D34:D38) -> 1485 | E39: =SUM(E34:E38) -> 1485 | F39: =SUM(F34:F38) -> 1485 | G39: =SUM(G34:G38) -> 1485 | H39: =SUM(H34:H38) -> 1485 | I39: =SUM(I34:I38) -> 1485 | J39: =SUM(J34:J38) -> 1510 | ... N39: =SUM(N34:N38) -> 1510 | O39: =SUM(B39:N39) -> 17295
A40: OPERATING PROFIT/(LOSS) | C40: =C33-C39 -> -1755.2403 | D40: =D33-D39 -> -2069.5286 | E40: =E33-E39 -> -1761.7928 | F40: =F33-F39 -> -1454.0571 | G40: =G33-G39 -> -1426.0812 | H40: =H33-H39 -> -1705.8409 | I40: =I33-I39 -> -1845.7208 | J40: =J33-J39 -> -2735.0091 | ... N40: =N33-N39 -> -1951.6818 | O40: =SUM(B40:N40) -> -24686.172
A41: Pre-launch one-time (incl. contingency) | B41: =Assumptions!$B$35 -> 9821 | C41: 0 | D41: 0 | E41: 0 | F41: 0 | G41: 0 | H41: 0 | I41: 0 | J41: 0 | K41: 0 | L41: 0 | M41: 0 | N41: 0 | O41: =SUM(B41:N41) -> 9821
...

Sheet Base
A1: Base scenario - monthly model (USD). Launch month M1 = Dec 2026
A2: Mature orders/day per beach | B2: 16
A3: Ramp months to maturity | B3: 4
A4: Avg product revenue per order $ (pre-promo) | B4: 8
A5: Promo discount % of product rev | B5: 0.06
A6: Coconut cost per nut $ | B6: 0.85
A7: Support/refund loss % revenue | B7: 0.03
A8: Runner guaranteed shift pay per position-day $ (loaded) | B8: 36
A9: Marketing $/month | B9: 800
A10: Delivery fee $ per order | B10: 2
A12: Line | B12: M0 | C12: M1 | D12: M2 | E12: M3 | F12: M4 | G12: M5 | H12: M6 | I12: M7 | J12: M8 | K12: M9 | L12: M10 | M12: M11 | N12: M12 | O12: 12-mo total
A13: Month index | B13: 0 | C13: 1 | D13: 2 | E13: 3 | F13: 4 | G13: 5 | H13: 6 | I13: 7 | J13: 8 | K13: 9 | L13: 10 | M13: 11 | N13: 12
A14: Calendar month | C14: Dec-26 | D14: Jan-27 | E14: Feb-27 | F14: Mar-27 | G14: Apr-27 | H14: May-27 | I14: Jun-27 | J14: Jul-27 | K14: Aug-27 | L14: Sep-27 | M14: Oct-27 | N14: Nov-27
A15: Season factor | C15: =Assumptions!$B$38 -> 1 | D15: =Assumptions!$B$39 -> 1.1 | E15: =Assumptions!$B$40 -> 1.1 | F15: =Assumptions!$B$41 -> 1.1 | G15: =Assumptions!$B$42 -> 0.9 | H15: =Assumptions!$B$43 -> 0.7 | I15: =Assumptions!$B$44 -> 0.6 | J15: =Assumptions!$B$45 -> 0.7 | K15: =Assumptions!$B$46 -> 0.7 | L15: =Assumptions!$B$47 -> 0.5 | M15: =Assumptions!$B$48 -> 0.5 | N15: =Assumptions!$B$49 -> 0.7
A16: New beaches opened (input plan) | C16: 1 | D16: 0 | E16: 0 | F16: 1 | G16: 0 | H16: 0 | I16: 2 | J16: 0 | K16: 0 | L16: 2 | M16: 0 | N16: 0
A17: Active beaches | B17: 0 | C17: =B17+C16 -> 1 | D17: =C17+D16 -> 1 | E17: =D17+E16 -> 1 | F17: =E17+F16 -> 2 | G17: =F17+G16 -> 2 | H17: =G17+H16 -> 2 | I17: =H17+I16 -> 4 | J17: =I17+J16 -> 4 | ... N17: =M17+N16 -> 6
A18: Beach-equivalents (ramped) | C18: =SUMPRODUCT($C$16:C16,(C$13-$C$13:C$13+1+$B$3-ABS(C$13-$C$13:C$13+1-$B$3))/(2*$B$3)) -> 0.25 | D18: =SUMPRODUCT($C$16:D16,(D$13-$C$13:D$13+1+$B$3-ABS(D$13-$C$13:D$13+1-$B$3))/(2*$B$3)) -> 0.5 | E18: =SUMPRODUCT($C$16:E16,(E$13-$C$13:E$13+1+$B$3-ABS(E$13-$C$13:E$13+1-$B$3))/(2*$B$3)) -> 0.75 | F18: =SUMPRODUCT($C$16:F16,(F$13-$C$13:F$13+1+$B$3-ABS(F$13-$C$13:F$13+1-$B$3))/(2*$B$3)) -> 1.25 | G18: =SUMPRODUCT($C$16:G16,(G$13-$C$13:G$13+1+$B$3-ABS(G$13-$C$13:G$13+1-$B$3))/(2*$B$3)) -> 1.5 | H18: =SUMPRODUCT($C$16:H16,(H$13-$C$13:H$13+1+$B$3-ABS(H$13-$C$13:H$13+1-$B$3))/(2*$B$3)) -> 1.75 | I18: =SUMPRODUCT($C$16:I16,(I$13-$C$13:I$13+1+$B$3-ABS(I$13-$C$13:I$13+1-$B$3))/(2*$B$3)) -> 2.5 | J18: =SUMPRODUCT($C$16:J16,(J$13-$C$13:J$13+1+$B$3-ABS(J$13-$C$13:J$13+1-$B$3))/(2*$B$3)) -> 3 | ... N18: =SUMPRODUCT($C$16:N16,(N$13-$C$13:N$13+1+$B$3-ABS(N$13-$C$13:N$13+1-$B$3))/(2*$B$3)) -> 5.5
A19: Orders/day (all beaches) | C19: =C18*$B$2*C15 -> 4 | D19: =D18*$B$2*D15 -> 8.8 | E19: =E18*$B$2*E15 -> 13.2 | F19: =F18*$B$2*F15 -> 22 | G19: =G18*$B$2*G15 -> 21.6 | H19: =H18*$B$2*H15 -> 19.6 | I19: =I18*$B$2*I15 -> 24 | J19: =J18*$B$2*J15 -> 33.6 | ... N19: =N18*$B$2*N15 -> 61.6
A20: Orders/month | C20: =C19*Assumptions!$B$19 -> 120 | D20: =D19*Assumptions!$B$19 -> 264 | E20: =E19*Assumptions!$B$19 -> 396 | F20: =F19*Assumptions!$B$19 -> 660 | G20: =G19*Assumptions!$B$19 -> 648 | H20: =H19*Assumptions!$B$19 -> 588 | I20: =I19*Assumptions!$B$19 -> 720 | J20: =J19*Assumptions!$B$19 -> 1008 | ... N20: =N19*Assumptions!$B$19 -> 1848 | O20: =SUM(B20:N20) -> 9708
A21: Product revenue (net of promo) | C21: =C20*$B$4*(1-$B$5) -> 902.4 | D21: =D20*$B$4*(1-$B$5) -> 1985.28 | E21: =E20*$B$4*(1-$B$5) -> 2977.92 | F21: =F20*$B$4*(1-$B$5) -> 4963.2 | G21: =G20*$B$4*(1-$B$5) -> 4872.96 | H21: =H20*$B$4*(1-$B$5) -> 4421.76 | I21: =I20*$B$4*(1-$B$5) -> 5414.4 | J21: =J20*$B$4*(1-$B$5) -> 7580.16 | ... N21: =N20*$B$4*(1-$B$5) -> 13896.96 | O21: =SUM(B21:N21) -> 73004.16
A22: Delivery fee revenue | C22: =C20*$B$10 -> 240 | D22: =D20*$B$10 -> 528 | E22: =E20*$B$10 -> 792 | F22: =F20*$B$10 -> 1320 | G22: =G20*$B$10 -> 1296 | H22: =H20*$B$10 -> 1176 | I22: =I20*$B$10 -> 1440 | J22: =J20*$B$10 -> 2016 | ... N22: =N20*$B$10 -> 3696 | O22: =SUM(B22:N22) -> 19416
A23: TOTAL REVENUE | C23: =C21+C22 -> 1142.4 | D23: =D21+D22 -> 2513.28 | E23: =E21+E22 -> 3769.92 | F23: =F21+F22 -> 6283.2 | G23: =G21+G22 -> 6168.96 | H23: =H21+H22 -> 5597.76 | I23: =I21+I22 -> 6854.4 | J23: =J21+J22 -> 9596.16 | ... N23: =N21+N22 -> 17592.96 | O23: =SUM(B23:N23) -> 92420.16
A24: Coconut cost | C24: =C20*Assumptions!$B$4*$B$6 -> 122.4 | D24: =D20*Assumptions!$B$4*$B$6 -> 269.28 | E24: =E20*Assumptions!$B$4*$B$6 -> 403.92 | F24: =F20*Assumptions!$B$4*$B$6 -> 673.2 | G24: =G20*Assumptions!$B$4*$B$6 -> 660.96 | H24: =H20*Assumptions!$B$4*$B$6 -> 599.76 | I24: =I20*Assumptions!$B$4*$B$6 -> 734.4 | J24: =J20*Assumptions!$B$4*$B$6 -> 1028.16 | ... N24: =N20*Assumptions!$B$4*$B$6 -> 1884.96 | O24: =SUM(B24:N24) -> 9902.16
A25: Supplies | C25: =C20*Assumptions!$B$5 -> 30 | D25: =D20*Assumptions!$B$5 -> 66 | E25: =E20*Assumptions!$B$5 -> 99 | F25: =F20*Assumptions!$B$5 -> 165 | G25: =G20*Assumptions!$B$5 -> 162 | H25: =H20*Assumptions!$B$5 -> 147 | I25: =I20*Assumptions!$B$5 -> 180 | J25: =J20*Assumptions!$B$5 -> 252 | ... N25: =N20*Assumptions!$B$5 -> 462 | O25: =SUM(B25:N25) -> 2427
A26: Payment fees | C26: =Assumptions!$B$6*(Assumptions!$B$7*C23+Assumptions!$B$8*C20) -> 76.4064 | D26: =Assumptions!$B$6*(Assumptions!$B$7*D23+Assumptions!$B$8*D20) -> 168.09408 | E26: =Assumptions!$B$6*(Assumptions!$B$7*E23+Assumptions!$B$8*E20) -> 252.14112 | F26: =Assumptions!$B$6*(Assumptions!$B$7*F23+Assumptions!$B$8*F20) -> 420.2352 | G26: =Assumptions!$B$6*(Assumptions!$B$7*G23+Assumptions!$B$8*G20) -> 412.59456 | H26: =Assumptions!$B$6*(Assumptions!$B$7*H23+Assumptions!$B$8*H20) -> 374.39136 | I26: =Assumptions!$B$6*(Assumptions!$B$7*I23+Assumptions!$B$8*I20) -> 458.4384 | J26: =Assumptions!$B$6*(Assumptions!$B$7*J23+Assumptions!$B$8*J20) -> 641.81376 | ... N26: =Assumptions!$B$6*(Assumptions!$B$7*N23+Assumptions!$B$8*N20) -> 1176.6586 | O26: =SUM(B26:N26) -> 6181.2778
A27: Cash shrinkage | C27: =(1-Assumptions!$B$6)*Assumptions!$B$9*C23 -> 6.8544 | D27: =(1-Assumptions!$B$6)*Assumptions!$B$9*D23 -> 15.07968 | E27: =(1-Assumptions!$B$6)*Assumptions!$B$9*E23 -> 22.61952 | F27: =(1-Assumptions!$B$6)*Assumptions!$B$9*F23 -> 37.6992 | G27: =(1-Assumptions!$B$6)*Assumptions!$B$9*G23 -> 37.01376 | H27: =(1-Assumptions!$B$6)*Assumptions!$B$9*H23 -> 33.58656 | I27: =(1-Assumptions!$B$6)*Assumptions!$B$9*I23 -> 41.1264 | J27: =(1-Assumptions!$B$6)*Assumptions!$B$9*J23 -> 57.57696 | ... N27: =(1-Assumptions!$B$6)*Assumptions!$B$9*N23 -> 105.55776 | O27: =SUM(B27:N27) -> 554.52096
A28: Support/refund losses | C28: =$B$7*C23 -> 34.272 | D28: =$B$7*D23 -> 75.3984 | E28: =$B$7*E23 -> 113.0976 | F28: =$B$7*F23 -> 188.496 | G28: =$B$7*G23 -> 185.0688 | H28: =$B$7*H23 -> 167.9328 | I28: =$B$7*I23 -> 205.632 | J28: =$B$7*J23 -> 287.8848 | ... N28: =$B$7*N23 -> 527.7888 | O28: =SUM(B28:N28) -> 2772.6048
A29: Total variable cost (excl. labour) | C29: =SUM(C24:C28) -> 269.9328 | D29: =SUM(D24:D28) -> 593.85216 | E29: =SUM(E24:E28) -> 890.77824 | F29: =SUM(F24:F28) -> 1484.6304 | G29: =SUM(G24:G28) -> 1457.6371 | H29: =SUM(H24:H28) -> 1322.6707 | I29: =SUM(I24:I28) -> 1619.5968 | J29: =SUM(J24:J28) -> 2267.4355 | ... N29: =SUM(N24:N28) -> 4156.9651 | O29: =SUM(B29:N29) -> 21837.564
A30: Contribution before labour | C30: =C23-C29 -> 872.4672 | D30: =D23-D29 -> 1919.4278 | E30: =E23-E29 -> 2879.1418 | F30: =F23-F29 -> 4798.5696 | G30: =G23-G29 -> 4711.3229 | H30: =H23-H29 -> 4275.0893 | I30: =I23-I29 -> 5234.8032 | J30: =J23-J29 -> 7328.7245 | ... N30: =N23-N29 -> 13435.995 | O30: =SUM(B30:N30) -> 70582.596
A31: Runner positions per beach | C31: =IF(C17=0,0,MAX(1,ROUNDUP(C19/C17/Assumptions!$B$10,0))) -> 1 | D31: =IF(D17=0,0,MAX(1,ROUNDUP(D19/D17/Assumptions!$B$10,0))) -> 1 | E31: =IF(E17=0,0,MAX(1,ROUNDUP(E19/E17/Assumptions!$B$10,0))) -> 1 | F31: =IF(F17=0,0,MAX(1,ROUNDUP(F19/F17/Assumptions!$B$10,0))) -> 1 | G31: =IF(G17=0,0,MAX(1,ROUNDUP(G19/G17/Assumptions!$B$10,0))) -> 1 | H31: =IF(H17=0,0,MAX(1,ROUNDUP(H19/H17/Assumptions!$B$10,0))) -> 1 | I31: =IF(I17=0,0,MAX(1,ROUNDUP(I19/I17/Assumptions!$B$10,0))) -> 1 | J31: =IF(J17=0,0,MAX(1,ROUNDUP(J19/J17/Assumptions!$B$10,0))) -> 1 | ... N31: =IF(N17=0,0,MAX(1,ROUNDUP(N19/N17/Assumptions!$B$10,0))) -> 1
A32: Runner labour (guaranteed + per-delivery) | C32: =C17*C31*$B$8*Assumptions!$B$19+C20*Assumptions!$B$11 -> 1200 | D32: =D17*D31*$B$8*Assumptions!$B$19+D20*Assumptions!$B$11 -> 1344 | E32: =E17*E31*$B$8*Assumptions!$B$19+E20*Assumptions!$B$11 -> 1476 | F32: =F17*F31*$B$8*Assumptions!$B$19+F20*Assumptions!$B$11 -> 2820 | G32: =G17*G31*$B$8*Assumptions!$B$19+G20*Assumptions!$B$11 -> 2808 | H32: =H17*H31*$B$8*Assumptions!$B$19+H20*Assumptions!$B$11 -> 2748 | I32: =I17*I31*$B$8*Assumptions!$B$19+I20*Assumptions!$B$11 -> 5040 | J32: =J17*J31*$B$8*Assumptions!$B$19+J20*Assumptions!$B$11 -> 5328 | ... N32: =N17*N31*$B$8*Assumptions!$B$19+N20*Assumptions!$B$11 -> 8328 | O32: =SUM(B32:N32) -> 51828
A33: Contribution after labour | C33: =C30-C32 -> -327.5328 | D33: =D30-D32 -> 575.42784 | E33: =E30-E32 -> 1403.1418 | F33: =F30-F32 -> 1978.5696 | G33: =G30-G32 -> 1903.3229 | H33: =H30-H32 -> 1527.0893 | I33: =I30-I32 -> 194.8032 | J33: =J30-J32 -> 2000.7245 | ... N33: =N30-N32 -> 5107.9949 | O33: =SUM(B33:N33) -> 18754.596
A34: Tech/SaaS | C34: =Assumptions!$B$13 -> 130 | D34: =Assumptions!$B$13 -> 130 | E34: =Assumptions!$B$13 -> 130 | F34: =Assumptions!$B$13 -> 130 | G34: =Assumptions!$B$13 -> 130 | H34: =Assumptions!$B$13 -> 130 | I34: =Assumptions!$B$13 -> 130 | J34: =Assumptions!$B$13 -> 130 | ... N34: =Assumptions!$B$13 -> 130 | O34: =SUM(B34:N34) -> 1560
A35: Accounting + insurance | C35: =Assumptions!$B$14+Assumptions!$B$15 -> 180 | D35: =Assumptions!$B$14+Assumptions!$B$15 -> 180 | E35: =Assumptions!$B$14+Assumptions!$B$15 -> 180 | F35: =Assumptions!$B$14+Assumptions!$B$15 -> 180 | G35: =Assumptions!$B$14+Assumptions!$B$15 -> 180 | H35: =Assumptions!$B$14+Assumptions!$B$15 -> 180 | I35: =Assumptions!$B$14+Assumptions!$B$15 -> 180 | J35: =Assumptions!$B$14+Assumptions!$B$15 -> 180 | ... N35: =Assumptions!$B$14+Assumptions!$B$15 -> 180 | O35: =SUM(B35:N35) -> 2160
A36: Phones/data | C36: =C17*Assumptions!$B$16 -> 25 | D36: =D17*Assumptions!$B$16 -> 25 | E36: =E17*Assumptions!$B$16 -> 25 | F36: =F17*Assumptions!$B$16 -> 50 | G36: =G17*Assumptions!$B$16 -> 50 | H36: =H17*Assumptions!$B$16 -> 50 | I36: =I17*Assumptions!$B$16 -> 100 | J36: =J17*Assumptions!$B$16 -> 100 | ... N36: =N17*Assumptions!$B$16 -> 150 | O36: =SUM(B36:N36) -> 975
A37: Ops coordinators | C37: =IF(C13>=2,ROUNDUP(C17/3,0)*Assumptions!$B$12,0) -> 0 | D37: =IF(D13>=2,ROUNDUP(D17/3,0)*Assumptions!$B$12,0) -> 650 | E37: =IF(E13>=2,ROUNDUP(E17/3,0)*Assumptions!$B$12,0) -> 650 | F37: =IF(F13>=2,ROUNDUP(F17/3,0)*Assumptions!$B$12,0) -> 650 | G37: =IF(G13>=2,ROUNDUP(G17/3,0)*Assumptions!$B$12,0) -> 650 | H37: =IF(H13>=2,ROUNDUP(H17/3,0)*Assumptions!$B$12,0) -> 650 | I37: =IF(I13>=2,ROUNDUP(I17/3,0)*Assumptions!$B$12,0) -> 1300 | J37: =IF(J13>=2,ROUNDUP(J17/3,0)*Assumptions!$B$12,0) -> 1300 | ... N37: =IF(N13>=2,ROUNDUP(N17/3,0)*Assumptions!$B$12,0) -> 1300 | O37: =SUM(B37:N37) -> 11050
A38: Marketing | C38: =$B$9 -> 800 | D38: =$B$9 -> 800 | E38: =$B$9 -> 800 | F38: =$B$9 -> 800 | G38: =$B$9 -> 800 | H38: =$B$9 -> 800 | I38: =$B$9 -> 800 | J38: =$B$9 -> 800 | ... N38: =$B$9 -> 800 | O38: =SUM(B38:N38) -> 9600
A39: Total fixed + marketing | C39: =SUM(C34:C38) -> 1135 | D39: =SUM(D34:D38) -> 1785 | E39: =SUM(E34:E38) -> 1785 | F39: =SUM(F34:F38) -> 1810 | G39: =SUM(G34:G38) -> 1810 | H39: =SUM(H34:H38) -> 1810 | I39: =SUM(I34:I38) -> 2510 | J39: =SUM(J34:J38) -> 2510 | ... N39: =SUM(N34:N38) -> 2560 | O39: =SUM(B39:N39) -> 25345
A40: OPERATING PROFIT/(LOSS) | C40: =C33-C39 -> -1462.5328 | D40: =D33-D39 -> -1209.5722 | E40: =E33-E39 -> -381.85824 | F40: =F33-F39 -> 168.5696 | G40: =G33-G39 -> 93.32288 | H40: =H33-H39 -> -282.91072 | I40: =I33-I39 -> -2315.1968 | J40: =J33-J39 -> -509.27552 | ... N40: =N33-N39 -> 2547.9949 | O40: =SUM(B40:N40) -> -6590.4035
A41: Pre-launch one-time (incl. contingency) | B41: =Assumptions!$B$35 -> 9821 | C41: 0 | D41: 0 | E41: 0 | F41: 0 | G41: 0 | H41: 0 | I41: 0 | J41: 0 | K41: 0 | L41: 0 | M41: 0 | N41: 0 | O41: =SUM(B41:N41) -> 9821
...

Sheet Aggressive
A1: Aggressive scenario - monthly model (USD). Launch month M1 = Dec 2026
A2: Mature orders/day per beach | B2: 24
A3: Ramp months to maturity | B3: 3
A4: Avg product revenue per order $ (pre-promo) | B4: 8.4
A5: Promo discount % of product rev | B5: 0.05
A6: Coconut cost per nut $ | B6: 0.7
A7: Support/refund loss % revenue | B7: 0.03
A8: Runner guaranteed shift pay per position-day $ (loaded) | B8: 36
A9: Marketing $/month | B9: 1500
A10: Delivery fee $ per order | B10: 2
A12: Line | B12: M0 | C12: M1 | D12: M2 | E12: M3 | F12: M4 | G12: M5 | H12: M6 | I12: M7 | J12: M8 | K12: M9 | L12: M10 | M12: M11 | N12: M12 | O12: 12-mo total
A13: Month index | B13: 0 | C13: 1 | D13: 2 | E13: 3 | F13: 4 | G13: 5 | H13: 6 | I13: 7 | J13: 8 | K13: 9 | L13: 10 | M13: 11 | N13: 12
A14: Calendar month | C14: Dec-26 | D14: Jan-27 | E14: Feb-27 | F14: Mar-27 | G14: Apr-27 | H14: May-27 | I14: Jun-27 | J14: Jul-27 | K14: Aug-27 | L14: Sep-27 | M14: Oct-27 | N14: Nov-27
A15: Season factor | C15: =Assumptions!$B$38 -> 1 | D15: =Assumptions!$B$39 -> 1.1 | E15: =Assumptions!$B$40 -> 1.1 | F15: =Assumptions!$B$41 -> 1.1 | G15: =Assumptions!$B$42 -> 0.9 | H15: =Assumptions!$B$43 -> 0.7 | I15: =Assumptions!$B$44 -> 0.6 | J15: =Assumptions!$B$45 -> 0.7 | K15: =Assumptions!$B$46 -> 0.7 | L15: =Assumptions!$B$47 -> 0.5 | M15: =Assumptions!$B$48 -> 0.5 | N15: =Assumptions!$B$49 -> 0.7
A16: New beaches opened (input plan) | C16: 1 | D16: 1 | E16: 2 | F16: 0 | G16: 2 | H16: 0 | I16: 3 | J16: 0 | K16: 3 | L16: 0 | M16: 2 | N16: 0
A17: Active beaches | B17: 0 | C17: =B17+C16 -> 1 | D17: =C17+D16 -> 2 | E17: =D17+E16 -> 4 | F17: =E17+F16 -> 4 | G17: =F17+G16 -> 6 | H17: =G17+H16 -> 6 | I17: =H17+I16 -> 9 | J17: =I17+J16 -> 9 | ... N17: =M17+N16 -> 14
A18: Beach-equivalents (ramped) | C18: =SUMPRODUCT($C$16:C16,(C$13-$C$13:C$13+1+$B$3-ABS(C$13-$C$13:C$13+1-$B$3))/(2*$B$3)) -> 0.33333333 | D18: =SUMPRODUCT($C$16:D16,(D$13-$C$13:D$13+1+$B$3-ABS(D$13-$C$13:D$13+1-$B$3))/(2*$B$3)) -> 1 | E18: =SUMPRODUCT($C$16:E16,(E$13-$C$13:E$13+1+$B$3-ABS(E$13-$C$13:E$13+1-$B$3))/(2*$B$3)) -> 2.3333333 | F18: =SUMPRODUCT($C$16:F16,(F$13-$C$13:F$13+1+$B$3-ABS(F$13-$C$13:F$13+1-$B$3))/(2*$B$3)) -> 3.3333333 | G18: =SUMPRODUCT($C$16:G16,(G$13-$C$13:G$13+1+$B$3-ABS(G$13-$C$13:G$13+1-$B$3))/(2*$B$3)) -> 4.6666667 | H18: =SUMPRODUCT($C$16:H16,(H$13-$C$13:H$13+1+$B$3-ABS(H$13-$C$13:H$13+1-$B$3))/(2*$B$3)) -> 5.3333333 | I18: =SUMPRODUCT($C$16:I16,(I$13-$C$13:I$13+1+$B$3-ABS(I$13-$C$13:I$13+1-$B$3))/(2*$B$3)) -> 7 | J18: =SUMPRODUCT($C$16:J16,(J$13-$C$13:J$13+1+$B$3-ABS(J$13-$C$13:J$13+1-$B$3))/(2*$B$3)) -> 8 | ... N18: =SUMPRODUCT($C$16:N16,(N$13-$C$13:N$13+1+$B$3-ABS(N$13-$C$13:N$13+1-$B$3))/(2*$B$3)) -> 13.333333
A19: Orders/day (all beaches) | C19: =C18*$B$2*C15 -> 8 | D19: =D18*$B$2*D15 -> 26.4 | E19: =E18*$B$2*E15 -> 61.6 | F19: =F18*$B$2*F15 -> 88 | G19: =G18*$B$2*G15 -> 100.8 | H19: =H18*$B$2*H15 -> 89.6 | I19: =I18*$B$2*I15 -> 100.8 | J19: =J18*$B$2*J15 -> 134.4 | ... N19: =N18*$B$2*N15 -> 224
A20: Orders/month | C20: =C19*Assumptions!$B$19 -> 240 | D20: =D19*Assumptions!$B$19 -> 792 | E20: =E19*Assumptions!$B$19 -> 1848 | F20: =F19*Assumptions!$B$19 -> 2640 | G20: =G19*Assumptions!$B$19 -> 3024 | H20: =H19*Assumptions!$B$19 -> 2688 | I20: =I19*Assumptions!$B$19 -> 3024 | J20: =J19*Assumptions!$B$19 -> 4032 | ... N20: =N19*Assumptions!$B$19 -> 6720 | O20: =SUM(B20:N20) -> 38568
A21: Product revenue (net of promo) | C21: =C20*$B$4*(1-$B$5) -> 1915.2 | D21: =D20*$B$4*(1-$B$5) -> 6320.16 | E21: =E20*$B$4*(1-$B$5) -> 14747.04 | F21: =F20*$B$4*(1-$B$5) -> 21067.2 | G21: =G20*$B$4*(1-$B$5) -> 24131.52 | H21: =H20*$B$4*(1-$B$5) -> 21450.24 | I21: =I20*$B$4*(1-$B$5) -> 24131.52 | J21: =J20*$B$4*(1-$B$5) -> 32175.36 | ... N21: =N20*$B$4*(1-$B$5) -> 53625.6 | O21: =SUM(B21:N21) -> 307772.64
A22: Delivery fee revenue | C22: =C20*$B$10 -> 480 | D22: =D20*$B$10 -> 1584 | E22: =E20*$B$10 -> 3696 | F22: =F20*$B$10 -> 5280 | G22: =G20*$B$10 -> 6048 | H22: =H20*$B$10 -> 5376 | I22: =I20*$B$10 -> 6048 | J22: =J20*$B$10 -> 8064 | ... N22: =N20*$B$10 -> 13440 | O22: =SUM(B22:N22) -> 77136
A23: TOTAL REVENUE | C23: =C21+C22 -> 2395.2 | D23: =D21+D22 -> 7904.16 | E23: =E21+E22 -> 18443.04 | F23: =F21+F22 -> 26347.2 | G23: =G21+G22 -> 30179.52 | H23: =H21+H22 -> 26826.24 | I23: =I21+I22 -> 30179.52 | J23: =J21+J22 -> 40239.36 | ... N23: =N21+N22 -> 67065.6 | O23: =SUM(B23:N23) -> 384908.64
A24: Coconut cost | C24: =C20*Assumptions!$B$4*$B$6 -> 201.6 | D24: =D20*Assumptions!$B$4*$B$6 -> 665.28 | E24: =E20*Assumptions!$B$4*$B$6 -> 1552.32 | F24: =F20*Assumptions!$B$4*$B$6 -> 2217.6 | G24: =G20*Assumptions!$B$4*$B$6 -> 2540.16 | H24: =H20*Assumptions!$B$4*$B$6 -> 2257.92 | I24: =I20*Assumptions!$B$4*$B$6 -> 2540.16 | J24: =J20*Assumptions!$B$4*$B$6 -> 3386.88 | ... N24: =N20*Assumptions!$B$4*$B$6 -> 5644.8 | O24: =SUM(B24:N24) -> 32397.12
A25: Supplies | C25: =C20*Assumptions!$B$5 -> 60 | D25: =D20*Assumptions!$B$5 -> 198 | E25: =E20*Assumptions!$B$5 -> 462 | F25: =F20*Assumptions!$B$5 -> 660 | G25: =G20*Assumptions!$B$5 -> 756 | H25: =H20*Assumptions!$B$5 -> 672 | I25: =I20*Assumptions!$B$5 -> 756 | J25: =J20*Assumptions!$B$5 -> 1008 | ... N25: =N20*Assumptions!$B$5 -> 1680 | O25: =SUM(B25:N25) -> 9642
A26: Payment fees | C26: =Assumptions!$B$6*(Assumptions!$B$7*C23+Assumptions!$B$8*C20) -> 156.7872 | D26: =Assumptions!$B$6*(Assumptions!$B$7*D23+Assumptions!$B$8*D20) -> 517.39776 | E26: =Assumptions!$B$6*(Assumptions!$B$7*E23+Assumptions!$B$8*E20) -> 1207.2614 | F26: =Assumptions!$B$6*(Assumptions!$B$7*F23+Assumptions!$B$8*F20) -> 1724.6592 | G26: =Assumptions!$B$6*(Assumptions!$B$7*G23+Assumptions!$B$8*G20) -> 1975.5187 | H26: =Assumptions!$B$6*(Assumptions!$B$7*H23+Assumptions!$B$8*H20) -> 1756.0166 | I26: =Assumptions!$B$6*(Assumptions!$B$7*I23+Assumptions!$B$8*I20) -> 1975.5187 | J26: =Assumptions!$B$6*(Assumptions!$B$7*J23+Assumptions!$B$8*J20) -> 2634.025 | ... N26: =Assumptions!$B$6*(Assumptions!$B$7*N23+Assumptions!$B$8*N20) -> 4390.0416 | O26: =SUM(B26:N26) -> 25195.703
A27: Cash shrinkage | C27: =(1-Assumptions!$B$6)*Assumptions!$B$9*C23 -> 14.3712 | D27: =(1-Assumptions!$B$6)*Assumptions!$B$9*D23 -> 47.42496 | E27: =(1-Assumptions!$B$6)*Assumptions!$B$9*E23 -> 110.65824 | F27: =(1-Assumptions!$B$6)*Assumptions!$B$9*F23 -> 158.0832 | G27: =(1-Assumptions!$B$6)*Assumptions!$B$9*G23 -> 181.07712 | H27: =(1-Assumptions!$B$6)*Assumptions!$B$9*H23 -> 160.95744 | I27: =(1-Assumptions!$B$6)*Assumptions!$B$9*I23 -> 181.07712 | J27: =(1-Assumptions!$B$6)*Assumptions!$B$9*J23 -> 241.43616 | ... N27: =(1-Assumptions!$B$6)*Assumptions!$B$9*N23 -> 402.3936 | O27: =SUM(B27:N27) -> 2309.4518
A28: Support/refund losses | C28: =$B$7*C23 -> 71.856 | D28: =$B$7*D23 -> 237.1248 | E28: =$B$7*E23 -> 553.2912 | F28: =$B$7*F23 -> 790.416 | G28: =$B$7*G23 -> 905.3856 | H28: =$B$7*H23 -> 804.7872 | I28: =$B$7*I23 -> 905.3856 | J28: =$B$7*J23 -> 1207.1808 | ... N28: =$B$7*N23 -> 2011.968 | O28: =SUM(B28:N28) -> 11547.259
A29: Total variable cost (excl. labour) | C29: =SUM(C24:C28) -> 504.6144 | D29: =SUM(D24:D28) -> 1665.2275 | E29: =SUM(E24:E28) -> 3885.5309 | F29: =SUM(F24:F28) -> 5550.7584 | G29: =SUM(G24:G28) -> 6358.1414 | H29: =SUM(H24:H28) -> 5651.6813 | I29: =SUM(I24:I28) -> 6358.1414 | J29: =SUM(J24:J28) -> 8477.5219 | ... N29: =SUM(N24:N28) -> 14129.203 | O29: =SUM(B29:N29) -> 81091.534
A30: Contribution before labour | C30: =C23-C29 -> 1890.5856 | D30: =D23-D29 -> 6238.9325 | E30: =E23-E29 -> 14557.509 | F30: =F23-F29 -> 20796.442 | G30: =G23-G29 -> 23821.379 | H30: =H23-H29 -> 21174.559 | I30: =I23-I29 -> 23821.379 | J30: =J23-J29 -> 31761.838 | ... N30: =N23-N29 -> 52936.397 | O30: =SUM(B30:N30) -> 303817.11
A31: Runner positions per beach | C31: =IF(C17=0,0,MAX(1,ROUNDUP(C19/C17/Assumptions!$B$10,0))) -> 1 | D31: =IF(D17=0,0,MAX(1,ROUNDUP(D19/D17/Assumptions!$B$10,0))) -> 1 | E31: =IF(E17=0,0,MAX(1,ROUNDUP(E19/E17/Assumptions!$B$10,0))) -> 1 | F31: =IF(F17=0,0,MAX(1,ROUNDUP(F19/F17/Assumptions!$B$10,0))) -> 2 | G31: =IF(G17=0,0,MAX(1,ROUNDUP(G19/G17/Assumptions!$B$10,0))) -> 1 | H31: =IF(H17=0,0,MAX(1,ROUNDUP(H19/H17/Assumptions!$B$10,0))) -> 1 | I31: =IF(I17=0,0,MAX(1,ROUNDUP(I19/I17/Assumptions!$B$10,0))) -> 1 | J31: =IF(J17=0,0,MAX(1,ROUNDUP(J19/J17/Assumptions!$B$10,0))) -> 1 | ... N31: =IF(N17=0,0,MAX(1,ROUNDUP(N19/N17/Assumptions!$B$10,0))) -> 1
A32: Runner labour (guaranteed + per-delivery) | C32: =C17*C31*$B$8*Assumptions!$B$19+C20*Assumptions!$B$11 -> 1320 | D32: =D17*D31*$B$8*Assumptions!$B$19+D20*Assumptions!$B$11 -> 2952 | E32: =E17*E31*$B$8*Assumptions!$B$19+E20*Assumptions!$B$11 -> 6168 | F32: =F17*F31*$B$8*Assumptions!$B$19+F20*Assumptions!$B$11 -> 11280 | G32: =G17*G31*$B$8*Assumptions!$B$19+G20*Assumptions!$B$11 -> 9504 | H32: =H17*H31*$B$8*Assumptions!$B$19+H20*Assumptions!$B$11 -> 9168 | I32: =I17*I31*$B$8*Assumptions!$B$19+I20*Assumptions!$B$11 -> 12744 | J32: =J17*J31*$B$8*Assumptions!$B$19+J20*Assumptions!$B$11 -> 13752 | ... N32: =N17*N31*$B$8*Assumptions!$B$19+N20*Assumptions!$B$11 -> 21840 | O32: =SUM(B32:N32) -> 143328
A33: Contribution after labour | C33: =C30-C32 -> 570.5856 | D33: =D30-D32 -> 3286.9325 | E33: =E30-E32 -> 8389.5091 | F33: =F30-F32 -> 9516.4416 | G33: =G30-G32 -> 14317.379 | H33: =H30-H32 -> 12006.559 | I33: =I30-I32 -> 11077.379 | J33: =J30-J32 -> 18009.838 | ... N33: =N30-N32 -> 31096.397 | O33: =SUM(B33:N33) -> 160489.11
A34: Tech/SaaS | C34: =Assumptions!$B$13 -> 130 | D34: =Assumptions!$B$13 -> 130 | E34: =Assumptions!$B$13 -> 130 | F34: =Assumptions!$B$13 -> 130 | G34: =Assumptions!$B$13 -> 130 | H34: =Assumptions!$B$13 -> 130 | I34: =Assumptions!$B$13 -> 130 | J34: =Assumptions!$B$13 -> 130 | ... N34: =Assumptions!$B$13 -> 130 | O34: =SUM(B34:N34) -> 1560
A35: Accounting + insurance | C35: =Assumptions!$B$14+Assumptions!$B$15 -> 180 | D35: =Assumptions!$B$14+Assumptions!$B$15 -> 180 | E35: =Assumptions!$B$14+Assumptions!$B$15 -> 180 | F35: =Assumptions!$B$14+Assumptions!$B$15 -> 180 | G35: =Assumptions!$B$14+Assumptions!$B$15 -> 180 | H35: =Assumptions!$B$14+Assumptions!$B$15 -> 180 | I35: =Assumptions!$B$14+Assumptions!$B$15 -> 180 | J35: =Assumptions!$B$14+Assumptions!$B$15 -> 180 | ... N35: =Assumptions!$B$14+Assumptions!$B$15 -> 180 | O35: =SUM(B35:N35) -> 2160
A36: Phones/data | C36: =C17*Assumptions!$B$16 -> 25 | D36: =D17*Assumptions!$B$16 -> 50 | E36: =E17*Assumptions!$B$16 -> 100 | F36: =F17*Assumptions!$B$16 -> 100 | G36: =G17*Assumptions!$B$16 -> 150 | H36: =H17*Assumptions!$B$16 -> 150 | I36: =I17*Assumptions!$B$16 -> 225 | J36: =J17*Assumptions!$B$16 -> 225 | ... N36: =N17*Assumptions!$B$16 -> 350 | O36: =SUM(B36:N36) -> 2325
A37: Ops coordinators | C37: =IF(C13>=2,ROUNDUP(C17/3,0)*Assumptions!$B$12,0) -> 0 | D37: =IF(D13>=2,ROUNDUP(D17/3,0)*Assumptions!$B$12,0) -> 650 | E37: =IF(E13>=2,ROUNDUP(E17/3,0)*Assumptions!$B$12,0) -> 1300 | F37: =IF(F13>=2,ROUNDUP(F17/3,0)*Assumptions!$B$12,0) -> 1300 | G37: =IF(G13>=2,ROUNDUP(G17/3,0)*Assumptions!$B$12,0) -> 1300 | H37: =IF(H13>=2,ROUNDUP(H17/3,0)*Assumptions!$B$12,0) -> 1300 | I37: =IF(I13>=2,ROUNDUP(I17/3,0)*Assumptions!$B$12,0) -> 1950 | J37: =IF(J13>=2,ROUNDUP(J17/3,0)*Assumptions!$B$12,0) -> 1950 | ... N37: =IF(N13>=2,ROUNDUP(N17/3,0)*Assumptions!$B$12,0) -> 3250 | O37: =SUM(B37:N37) -> 21450
A38: Marketing | C38: =$B$9 -> 1500 | D38: =$B$9 -> 1500 | E38: =$B$9 -> 1500 | F38: =$B$9 -> 1500 | G38: =$B$9 -> 1500 | H38: =$B$9 -> 1500 | I38: =$B$9 -> 1500 | J38: =$B$9 -> 1500 | ... N38: =$B$9 -> 1500 | O38: =SUM(B38:N38) -> 18000
A39: Total fixed + marketing | C39: =SUM(C34:C38) -> 1835 | D39: =SUM(D34:D38) -> 2510 | E39: =SUM(E34:E38) -> 3210 | F39: =SUM(F34:F38) -> 3210 | G39: =SUM(G34:G38) -> 3260 | H39: =SUM(H34:H38) -> 3260 | I39: =SUM(I34:I38) -> 3985 | J39: =SUM(J34:J38) -> 3985 | ... N39: =SUM(N34:N38) -> 5410 | O39: =SUM(B39:N39) -> 45495
A40: OPERATING PROFIT/(LOSS) | C40: =C33-C39 -> -1264.4144 | D40: =D33-D39 -> 776.93248 | E40: =E33-E39 -> 5179.5091 | F40: =F33-F39 -> 6306.4416 | G40: =G33-G39 -> 11057.379 | H40: =H33-H39 -> 8746.5587 | I40: =I33-I39 -> 7092.3786 | J40: =J33-J39 -> 14024.838 | ... N40: =N33-N39 -> 25686.397 | O40: =SUM(B40:N40) -> 114994.11
A41: Pre-launch one-time (incl. contingency) | B41: =Assumptions!$B$35 -> 9821 | C41: 0 | D41: 0 | E41: 0 | F41: 0 | G41: 0 | H41: 0 | I41: 0 | J41: 0 | K41: 0 | L41: 0 | M41: 0 | N41: 0 | O41: =SUM(B41:N41) -> 9821
...

Sheet BreakEven
A1: Unit economics and break-even (Base scenario parameters) - USD
A3: Revenue per order (net product + delivery) | B3: =Base!B4*(1-Base!B5)+Base!B10 -> 9.52
A4: Coconut cost per order | B4: =Assumptions!$B$4*Base!B6 -> 1.02
A5: Supplies | B5: =Assumptions!$B$5 -> 0.25
A6: Payment fees | B6: =Assumptions!$B$6*(Assumptions!$B$7*B3+Assumptions!$B$8) -> 0.63672
A7: Cash shrinkage | B7: =(1-Assumptions!$B$6)*Assumptions!$B$9*B3 -> 0.05712
A8: Support/refund losses | B8: =Base!B7*B3 -> 0.2856
A9: Per-delivery runner pay | B9: =Assumptions!$B$11 -> 1
A10: CONTRIBUTION PER ORDER | B10: =B3-SUM(B4:B9) -> 6.27056
A11: Contribution margin % | B11: =B10/B3 -> 0.65867227
A12: Fixed cost per beach per month (guaranteed shift + phone + coordinator share) | B12: =Base!B8*Assumptions!$B$19+Assumptions!$B$16+Assumptions!$B$12/3 -> 1321.6667
A13: Central fixed per month (tech, accounting, insurance, marketing) | B13: =Assumptions!$B$13+Assumptions!$B$14+Assumptions!$B$15+Base!B9 -> 1110
A14: Setup capex amortised over 12 months per beach | B14: =Assumptions!$B$17/12 -> 141.66667
A15: Break-even orders/day for ONE beach, beach-level costs only | B15: =B12/(B10*Assumptions!$B$19) -> 7.0257769
A16: Break-even orders/day for ONE beach incl. central costs + setup | B16: =(B12+B13+B14)/(B10*Assumptions!$B$19) -> 13.679445
A17: Break-even orders/day per beach when central costs spread over 4 beaches | B17: =(B12+B13/4+B14)/(B10*Assumptions!$B$19) -> 9.2540025
A18: Contribution per order if mature (16/day) incl. guaranteed shift pay | B18: =B10-Base!B8/Base!B2 -> 4.02056
A19: Revenue per order JMD | B19: =B3*Assumptions!$B$3 -> 1504.16
